<robot name="planar_3dof">
<material name="grey">
	<color rgba="0.7 0.7 0.7 1.0"/>
</material>
<link name="base_link"/>
<link name="link_1">
	<visual>
		<geometry>
			<mesh filename="package://gripper_description/meshes/visual/arm_link.stl"/>
		</geometry>
		<material name="grey"/>
	</visual>
	<collision>
		<geometry>
			<mesh filename="package://gripper_description/meshes/collision/arm_link.stl"/>
		</geometry>
	</collision>
</link>
<link name="link_2">
	<visual>
		<geometry>
			<mesh filename="package://gripper_description/meshes/visual/arm_link.stl"/>
		</geometry>
		<material name="grey"/>
	</visual>
	<collision>
		<geometry>
			<mesh filename="package://gripper_description/meshes/collision/arm_link.stl"/>
		</geometry>
	</collision>
</link>
<link name="gripper">
	<visual>
		<geometry>
			<mesh filename="package://gripper_description/meshes/visual/gripper.stl"/>
		</geometry>
		<material name="grey"/>
	</visual>
	<collision>
		<geometry>
			<mesh filename="package://gripper_description/meshes/collision/gripper.stl"/>
		</geometry>
	</collision>
</link>
<joint name="joint_1" type="revolute">
	<parent link="base_link"/>
	<child link="link_1"/>
	<origin xyz="0 0 0.1" rpy="0 -1.57 0"/>
	<axis xyz="0 0 1" />
	<limit lower="-1.57" upper="1.57" effort="0" velocity="0.5"/>
</joint>
<joint name="joint_2" type="revolute">
	<parent link="link_1"/>
	<child link="link_2"/>
	<origin xyz="0.5 0.0 0.0" rpy="0 0 0"/>
	<axis xyz="0 0 1" />
	<limit lower="-1.57" upper="1.57" effort="0" velocity="0.5"/>
</joint>
<joint name="joint_3" type="revolute">
	<parent link="link_2"/>
	<child link="gripper"/>
	<origin xyz="0.5 0.0 0.0" rpy="0 0 0"/>
	<axis xyz="0 0 1" />
	<limit lower="-1.57" upper="1.57" effort="0" velocity="0.5"/>
</joint>
</robot>
